ERROR - django.request |                        2020-02-06 17:27:23,622  
Internal Server Error: /
---
Traceback (most recent call last):
  File "/home/ataparlarr/.virtualenvs/webrover/lib/python3.5/site-packages/django/core/handlers/exception.py", line 35, in inner
    response = get_response(request)
  File "/home/ataparlarr/.virtualenvs/webrover/lib/python3.5/site-packages/django/core/handlers/base.py", line 128, in _get_response
    response = self.process_exception_by_middleware(e, request)
  File "/home/ataparlarr/.virtualenvs/webrover/lib/python3.5/site-packages/django/core/handlers/base.py", line 126, in _get_response
    response = wrapped_callback(request, *callback_args, **callback_kwargs)
  File "/home/ataparlarr/.virtualenvs/webrover/lib/python3.5/site-packages/django/views/generic/base.py", line 69, in view
    return self.dispatch(request, *args, **kwargs)
  File "/home/ataparlarr/.virtualenvs/webrover/lib/python3.5/site-packages/django/views/generic/base.py", line 89, in dispatch
    return handler(request, *args, **kwargs)
  File "/home/ataparlarr/.virtualenvs/webrover/lib/python3.5/site-packages/django/views/generic/base.py", line 150, in get
    context = self.get_context_data(**kwargs)
  File "/home/ataparlarr/Desktop/rover-website/itu_rover/main/views.py", line 60, in get_context_data
    r_year = str(OldYear.objects.all().order_by('-year')[0].year)
  File "/home/ataparlarr/.virtualenvs/webrover/lib/python3.5/site-packages/django/db/models/query.py", line 307, in __getitem__
    return qs._result_cache[0]
IndexError: list index out of range
